<?xml version="1.0" encoding="utf-8"?>
<!-- This URDF was automatically created by SolidWorks to URDF Exporter! Originally created by Stephen Brawner (brawner@gmail.com) 
     Commit Version: 1.5.1-0-g916b5db  Build Version: 1.5.7152.31018
     For more information, please see http://wiki.ros.org/sw_urdf_exporter -->
<robot
  name="igv_final">
  <link
    name="base_link">
    <inertial>
      <origin
        xyz="0.0347114051526544 0.0820892496165727 0.123777607901242"
        rpy="0 0 0" />
      <mass
        value="0.325132741228718" />
      <inertia
        ixx="0.000351943944995061"
        ixy="5.1299138728878E-22"
        ixz="-8.27180612553028E-21"
        iyy="0.000955337745983216"
        iyz="-2.11758236813573E-21"
        izz="0.000624650438049591" />
    </inertial>
    <visual>
      <origin
        xyz="0 0 0"
        rpy="0 0 0" />
      <geometry>
        <mesh
          filename="package://igv_final/meshes/base_link.STL" />
      </geometry>
      <material
        name="">
        <color
          rgba="0.792156862745098 0.819607843137255 0.933333333333333 1" />
      </material>
    </visual>
    <collision>
      <origin
        xyz="0 0 0"
        rpy="0 0 0" />
      <geometry>
        <mesh
          filename="package://igv_final/meshes/base_link.STL" />
      </geometry>
    </collision>
  </link>
  <link
    name="wheel1">
    <inertial>
      <origin
        xyz="0 1.38777878078145E-17 0.00999999999999998"
        rpy="0 0 0" />
      <mass
        value="0.0502654824574367" />
      <inertia
        ixx="1.42418866962737E-05"
        ixy="-6.72929976440541E-39"
        ixz="2.82344315751433E-22"
        iyy="1.42418866962737E-05"
        iyz="-3.64261656012912E-38"
        izz="2.51327412287183E-05" />
    </inertial>
    <visual>
      <origin
        xyz="0 0 0"
        rpy="0 0 0" />
      <geometry>
        <mesh
          filename="package://igv_final/meshes/wheel1.STL" />
      </geometry>
      <material
        name="">
        <color
          rgba="0.792156862745098 0.819607843137255 0.933333333333333 1" />
      </material>
    </visual>
    <collision>
      <origin
        xyz="0 0 0"
        rpy="0 0 0" />
      <geometry>
        <mesh
          filename="package://igv_final/meshes/wheel1.STL" />
      </geometry>
    </collision>
  </link>
  <joint
    name="wheel1"
    type="continuous">
    <origin
      xyz="0.079711 -0.17378 0.082089"
      rpy="1.5708 0 0" />
    <parent
      link="base_link" />
    <child
      link="wheel1" />
    <axis
      xyz="0 0 1" />
  </joint>
  <link
    name="wheel4">
    <inertial>
      <origin
        xyz="-1.38777878078145E-17 0 0.01"
        rpy="0 0 0" />
      <mass
        value="0.0502654824574367" />
      <inertia
        ixx="1.42418866962737E-05"
        ixy="-6.72929976440553E-39"
        ixz="-3.52930394689292E-23"
        iyy="1.42418866962737E-05"
        iyz="-3.64261656012912E-38"
        izz="2.51327412287184E-05" />
    </inertial>
    <visual>
      <origin
        xyz="0 0 0"
        rpy="0 0 0" />
      <geometry>
        <mesh
          filename="package://igv_final/meshes/wheel4.STL" />
      </geometry>
      <material
        name="">
        <color
          rgba="0.792156862745098 0.819607843137255 0.933333333333333 1" />
      </material>
    </visual>
    <collision>
      <origin
        xyz="0 0 0"
        rpy="0 0 0" />
      <geometry>
        <mesh
          filename="package://igv_final/meshes/wheel4.STL" />
      </geometry>
    </collision>
  </link>
  <joint
    name="wheel4"
    type="continuous">
    <origin
      xyz="0.079711 -0.053778 0.082089"
      rpy="1.5708 0 0" />
    <parent
      link="base_link" />
    <child
      link="wheel4" />
    <axis
      xyz="0 0 1" />
  </joint>
  <link
    name="wheel2">
    <inertial>
      <origin
        xyz="1.73472347597681E-18 1.38777878078145E-17 0.00999999999999998"
        rpy="0 0 0" />
      <mass
        value="0.0502654824574367" />
      <inertia
        ixx="1.42418866962737E-05"
        ixy="-6.72929976440541E-39"
        ixz="2.82344315751433E-22"
        iyy="1.42418866962737E-05"
        iyz="-3.64261656012912E-38"
        izz="2.51327412287183E-05" />
    </inertial>
    <visual>
      <origin
        xyz="0 0 0"
        rpy="0 0 0" />
      <geometry>
        <mesh
          filename="package://igv_final/meshes/wheel2.STL" />
      </geometry>
      <material
        name="">
        <color
          rgba="0.792156862745098 0.819607843137255 0.933333333333333 1" />
      </material>
    </visual>
    <collision>
      <origin
        xyz="0 0 0"
        rpy="0 0 0" />
      <geometry>
        <mesh
          filename="package://igv_final/meshes/wheel2.STL" />
      </geometry>
    </collision>
  </link>
  <joint
    name="wheel2"
    type="continuous">
    <origin
      xyz="-0.010289 -0.17378 0.082089"
      rpy="1.5708 0 0" />
    <parent
      link="base_link" />
    <child
      link="wheel2" />
    <axis
      xyz="0 0 1" />
  </joint>
  <link
    name="wheel3">
    <inertial>
      <origin
        xyz="-1.73472347597681E-18 0 0.01"
        rpy="0 0 0" />
      <mass
        value="0.0502654824574367" />
      <inertia
        ixx="1.42418866962737E-05"
        ixy="-6.72929976440553E-39"
        ixz="-3.52930394689292E-23"
        iyy="1.42418866962737E-05"
        iyz="-3.64261656012912E-38"
        izz="2.51327412287184E-05" />
    </inertial>
    <visual>
      <origin
        xyz="0 0 0"
        rpy="0 0 0" />
      <geometry>
        <mesh
          filename="package://igv_final/meshes/wheel3.STL" />
      </geometry>
      <material
        name="">
        <color
          rgba="0.792156862745098 0.819607843137255 0.933333333333333 1" />
      </material>
    </visual>
    <collision>
      <origin
        xyz="0 0 0"
        rpy="0 0 0" />
      <geometry>
        <mesh
          filename="package://igv_final/meshes/wheel3.STL" />
      </geometry>
    </collision>
  </link>
  <joint
    name="wheel3"
    type="continuous">
    <origin
      xyz="-0.010289 -0.053778 0.082089"
      rpy="1.5708 0 0" />
    <parent
      link="base_link" />
    <child
      link="wheel3" />
    <axis
      xyz="0 0 1" />
  </joint>
</robot>